Workbook

Sheet Nexops
B3: N | C3: NEXOPS
C4: Операционный штаб для МСБ · Выстраиваем систему в вашем бизнесе
C7: ● Операционный директор на аутсорсе | F7: ● Трекинг команды
C8: ● Диагностика бизнеса | F8: ● Стратегическая сессия
C9: ● ИИ-автоматизация | F9: ● Пул экспертов под вашу нишу
C11: от 90 000 ₽/мес | E11: Онлайн + офлайн · Вся Россия | G11: opdir.nexops.ru
C15: О ШАБЛОНЕ — ЕЖЕНЕДЕЛЬНЫЙ ТРЕКИНГ-ОТЧЁТ РНП
C16: Этот файл — операционный инструмент для еженедельного разбора с трекером или опердиром. Вносите плановые и фактические данные — файл считает всё автоматически.
C18: [ РНП ] | D18: [ Маркетинг ] | E18: [ Продажи ] | F18: [ Инструкция ]
C19: Главный экран | D19: Детализация по каналам | E19: По менеджерам | F19: Как использовать
C20: Сводка KPI, воронка, конверсии, задачи, блокеры. Открывайте перед каждой встречей. | D20: TG, посевы, YouTube, Авито — план/факт по дням. Прогноз считается автоматически. | E20: Воронка каждого менеджера по дням. Итоги агрегируются. CV воронки — авто. | F20: Логика работы, цветовая кодировка и правила заполнения шаблона.
C23: ● Принимаем заявки
C24: Получите бесплатный разбор вашей ситуации — 30 минут с экспертом Nexops
C25: Покажем узкие места, дадим конкретный первый шаг. Без продажи в лоб.
C27: Опердир + Трекинг | D27: Диагностика | E27: Стратсессия | F27: ИИ-автоматизация
C28: opdir.nexops.ru | D28: diagnostika.nexops.ru | E28: stratsessiya.nexops.ru | F28: ai.nexops.ru
C30: © 2026 Nexops · Операционный консалтинг · opdir.nexops.ru

Sheet Инструкция
B3: Трекинг-отчёт РНП — Nexops. Инструкция по использованию
B4: opdir.nexops.ru · Операционный штаб для МСБ
B7: 1. ЛИСТ «ПРОДАЖИ»
B8: Заполняйте ежедневно: сколько лидов получено, КП отправлено, встреч назначено/проведено, продаж совершено, сумму. Вносите данные по каждому менеджеру. Итоги агрегируются автоматически.
B10: 2. ЛИСТ «МАРКЕТИНГ»
B11: Вносите ежедневные данные по каждому каналу: расходы, кол-во подписчиков, контентных единиц, переходов и лидов. Факт за месяц и недели считается автоматически через SUM.
B13: 3. ЛИСТ «РНП»
B14: Главный экран. Вносите плановые показатели (столбец ПЛАН). Фактические данные и % выполнения считаются автоматически. Зелёный = план выполнен, красный = отставание. Используйте для встречи с трекером.
B16: 4. ЦВЕТОВАЯ ИНДИКАЦИЯ
B17: Зелёный фон % — факт ≥ плана. Красный фон — отставание. Жёлтый фон задачи — «В работе». Красный фон задачи — «Блокер». Зелёный фон задачи — «Выполнено'.
B19: 5. КОНВЕРСИИ ВОРОНКИ
B20: Рассчитываются автоматически из данных воронки: лиды → КП → встречи → продажи. Следите за слабым звеном — оно и есть текущий ограничитель.
... B26: © 2026 Nexops · opdir.nexops.ru · Операционный консалтинг для МСБ

Sheet РНП
B2: РНП — Результаты недели с планом | G2: Nexops · Операционный штаб · opdir.nexops.ru
B3: Месяц: | D3: Компания: | G3: Неделя #: | I3: Период: | M3: Трекер:
C4: Апрель 2026 | E4: ООО Компания | H4: 1 | J4: 01.04–07.04 | N4: Денис Матюшин
B6: Метрика | C6: ЗА МЕСЯЦ | G6: НЕДЕЛЯ 1 | K6: НЕДЕЛЯ 2 | O6: НЕДЕЛЯ 3 | S6: НЕДЕЛЯ 4
C7: ПЛАН | D7: ФАКТ | E7: % | G7: ПЛАН | H7: ФАКТ | I7: % | K7: ПЛАН | L7: ФАКТ | M7: % | O7: ПЛАН | P7: ФАКТ | Q7: % | S7: ПЛАН | T7: ФАКТ | U7: %
B8: КЛЮЧЕВЫЕ KPI МЕСЯЦА — сводка
B9: Выручка / Бюджет (₽) | D9: =Маркетинг!D8 | E9: =IFERROR(D9/C9,"") | G9: =IFERROR(C9/4,"") | I9: =IFERROR(H9/G9,"") | K9: =IFERROR(C9/4,"") | M9: =IFERROR(L9/K9,"") | O9: =IFERROR(C9/4,"") | Q9: =IFERROR(P9/O9,"") | S9: =IFERROR(C9/4,"") | U9: =IFERROR(T9/S9,"")
B10: Кол-во новых лидов | D10: =Продажи!D6 | E10: =IFERROR(D10/C10,"") | G10: =IFERROR(C10/4,"") | I10: =IFERROR(H10/G10,"") | K10: =IFERROR(C10/4,"") | M10: =IFERROR(L10/K10,"") | O10: =IFERROR(C10/4,"") | Q10: =IFERROR(P10/O10,"") | S10: =IFERROR(C10/4,"") | U10: =IFERROR(T10/S10,"")
B11: Кол-во продаж | D11: =Продажи!D10 | E11: =IFERROR(D11/C11,"") | G11: =IFERROR(C11/4,"") | I11: =IFERROR(H11/G11,"") | K11: =IFERROR(C11/4,"") | M11: =IFERROR(L11/K11,"") | O11: =IFERROR(C11/4,"") | Q11: =IFERROR(P11/O11,"") | S11: =IFERROR(C11/4,"") | U11: =IFERROR(T11/S11,"")
B12: Сумма продаж (₽) | D12: =Продажи!D11 | E12: =IFERROR(D12/C12,"") | G12: =IFERROR(C12/4,"") | I12: =IFERROR(H12/G12,"") | K12: =IFERROR(C12/4,"") | M12: =IFERROR(L12/K12,"") | O12: =IFERROR(C12/4,"") | Q12: =IFERROR(P12/O12,"") | S12: =IFERROR(C12/4,"") | U12: =IFERROR(T12/S12,"")
B13: Стоимость лида (₽) | D13: =IFERROR(D18/D32,"") | E13: =IFERROR(D13/C13,"") | G13: =IFERROR(C13/4,"") | I13: =IFERROR(H13/G13,"") | K13: =IFERROR(C13/4,"") | M13: =IFERROR(L13/K13,"") | O13: =IFERROR(C13/4,"") | Q13: =IFERROR(P13/O13,"") | S13: =IFERROR(C13/4,"") | U13: =IFERROR(T13/S13,"")
B14: Стоимость клиента (₽) | D14: =IFERROR(D18/D36,"") | E14: =IFERROR(D14/C14,"") | G14: =IFERROR(C14/4,"") | I14: =IFERROR(H14/G14,"") | K14: =IFERROR(C14/4,"") | M14: =IFERROR(L14/K14,"") | O14: =IFERROR(C14/4,"") | Q14: =IFERROR(P14/O14,"") | S14: =IFERROR(C14/4,"") | U14: =IFERROR(T14/S14,"")
B15: Средний чек (₽) | D15: =IFERROR(D37/D36,"") | E15: =IFERROR(D15/C15,"") | G15: =IFERROR(C15/4,"") | I15: =IFERROR(H15/G15,"") | K15: =IFERROR(C15/4,"") | M15: =IFERROR(L15/K15,"") | O15: =IFERROR(C15/4,"") | Q15: =IFERROR(P15/O15,"") | S15: =IFERROR(C15/4,"") | U15: =IFERROR(T15/S15,"")
B17: МАРКЕТИНГ — бюджет и каналы
B18: Суммарный маркетинговый бюджет (₽) | D18: =Маркетинг!D8 | E18: =IFERROR(D18/C18,"") | G18: =IFERROR(C18/4,"") | I18: =IFERROR(H18/G18,"") | K18: =IFERROR(C18/4,"") | M18: =IFERROR(L18/K18,"") | O18: =IFERROR(C18/4,"") | Q18: =IFERROR(P18/O18,"") | S18: =IFERROR(C18/4,"") | U18: =IFERROR(T18/S18,"")
B19: Стоимость лида — общая (₽) | D19: =IFERROR(H19+L19+P19+T19,"") | E19: =IFERROR(D19/C19,"") | G19: =IFERROR(C19/4,"") | I19: =IFERROR(H19/G19,"") | K19: =IFERROR(C19/4,"") | M19: =IFERROR(L19/K19,"") | O19: =IFERROR(C19/4,"") | Q19: =IFERROR(P19/O19,"") | S19: =IFERROR(C19/4,"") | U19: =IFERROR(T19/S19,"")
B20: Стоимость клиента — общая (₽) | D20: =IFERROR(H20+L20+P20+T20,"") | E20: =IFERROR(D20/C20,"") | G20: =IFERROR(C20/4,"") | I20: =IFERROR(H20/G20,"") | K20: =IFERROR(C20/4,"") | M20: =IFERROR(L20/K20,"") | O20: =IFERROR(C20/4,"") | Q20: =IFERROR(P20/O20,"") | S20: =IFERROR(C20/4,"") | U20: =IFERROR(T20/S20,"")
B21: Лиды из Telegram-канала | D21: =Маркетинг!D18 | E21: =IFERROR(D21/C21,"") | G21: =IFERROR(C21/4,"") | I21: =IFERROR(H21/G21,"") | K21: =IFERROR(C21/4,"") | M21: =IFERROR(L21/K21,"") | O21: =IFERROR(C21/4,"") | Q21: =IFERROR(P21/O21,"") | S21: =IFERROR(C21/4,"") | U21: =IFERROR(T21/S21,"")
B22: Лиды из Instagram / посевов | D22: =Маркетинг!D18 | E22: =IFERROR(D22/C22,"") | G22: =IFERROR(C22/4,"") | I22: =IFERROR(H22/G22,"") | K22: =IFERROR(C22/4,"") | M22: =IFERROR(L22/K22,"") | O22: =IFERROR(C22/4,"") | Q22: =IFERROR(P22/O22,"") | S22: =IFERROR(C22/4,"") | U22: =IFERROR(T22/S22,"")
B23: Лиды из YouTube | D23: =IFERROR(H23+L23+P23+T23,"") | E23: =IFERROR(D23/C23,"") | G23: =IFERROR(C23/4,"") | I23: =IFERROR(H23/G23,"") | K23: =IFERROR(C23/4,"") | M23: =IFERROR(L23/K23,"") | O23: =IFERROR(C23/4,"") | Q23: =IFERROR(P23/O23,"") | S23: =IFERROR(C23/4,"") | U23: =IFERROR(T23/S23,"")
B24: Лиды из Авито | D24: =IFERROR(H24+L24+P24+T24,"") | E24: =IFERROR(D24/C24,"") | G24: =IFERROR(C24/4,"") | I24: =IFERROR(H24/G24,"") | K24: =IFERROR(C24/4,"") | M24: =IFERROR(L24/K24,"") | O24: =IFERROR(C24/4,"") | Q24: =IFERROR(P24/O24,"") | S24: =IFERROR(C24/4,"") | U24: =IFERROR(T24/S24,"")
B25: Лиды по рекомендации | D25: =IFERROR(H25+L25+P25+T25,"") | E25: =IFERROR(D25/C25,"") | G25: =IFERROR(C25/4,"") | I25: =IFERROR(H25/G25,"") | K25: =IFERROR(C25/4,"") | M25: =IFERROR(L25/K25,"") | O25: =IFERROR(C25/4,"") | Q25: =IFERROR(P25/O25,"") | S25: =IFERROR(C25/4,"") | U25: =IFERROR(T25/S25,"")
B26: Лиды — другой канал | D26: =IFERROR(H26+L26+P26+T26,"") | E26: =IFERROR(D26/C26,"") | G26: =IFERROR(C26/4,"") | I26: =IFERROR(H26/G26,"") | K26: =IFERROR(C26/4,"") | M26: =IFERROR(L26/K26,"") | O26: =IFERROR(C26/4,"") | Q26: =IFERROR(P26/O26,"") | S26: =IFERROR(C26/4,"") | U26: =IFERROR(T26/S26,"")
B27: Контентные единицы (шт. постов/видео) | D27: =Маркетинг!D32 | E27: =IFERROR(D27/C27,"") | G27: =IFERROR(C27/4,"") | I27: =IFERROR(H27/G27,"") | K27: =IFERROR(C27/4,"") | M27: =IFERROR(L27/K27,"") | O27: =IFERROR(C27/4,"") | Q27: =IFERROR(P27/O27,"") | S27: =IFERROR(C27/4,"") | U27: =IFERROR(T27/S27,"")
B28: Подписчики Telegram (накопительно) | D28: =IFERROR(H28+L28+P28+T28,"") | E28: =IFERROR(D28/C28,"") | G28: =IFERROR(C28/4,"") | I28: =IFERROR(H28/G28,"") | K28: =IFERROR(C28/4,"") | M28: =IFERROR(L28/K28,"") | O28: =IFERROR(C28/4,"") | Q28: =IFERROR(P28/O28,"") | S28: =IFERROR(C28/4,"") | U28: =IFERROR(T28/S28,"")
B29: Прирост подписчиков за неделю | D29: =IFERROR(H29+L29+P29+T29,"") | E29: =IFERROR(D29/C29,"") | G29: =IFERROR(C29/4,"") | I29: =IFERROR(H29/G29,"") | K29: =IFERROR(C29/4,"") | M29: =IFERROR(L29/K29,"") | O29: =IFERROR(C29/4,"") | Q29: =IFERROR(P29/O29,"") | S29: =IFERROR(C29/4,"") | U29: =IFERROR(T29/S29,"")
B31: ВОРОНКА ПРОДАЖ
B32: Всего новых лидов (шт.) | D32: =Продажи!D6 | E32: =IFERROR(D32/C32,"") | G32: =IFERROR(C32/4,"") | I32: =IFERROR(H32/G32,"") | K32: =IFERROR(C32/4,"") | M32: =IFERROR(L32/K32,"") | O32: =IFERROR(C32/4,"") | Q32: =IFERROR(P32/O32,"") | S32: =IFERROR(C32/4,"") | U32: =IFERROR(T32/S32,"")
B33: КП / предложение отправлено (шт.) | D33: =Продажи!D7 | E33: =IFERROR(D33/C33,"") | G33: =IFERROR(C33/4,"") | I33: =IFERROR(H33/G33,"") | K33: =IFERROR(C33/4,"") | M33: =IFERROR(L33/K33,"") | O33: =IFERROR(C33/4,"") | Q33: =IFERROR(P33/O33,"") | S33: =IFERROR(C33/4,"") | U33: =IFERROR(T33/S33,"")
B34: Назначено встреч (шт.) | D34: =Продажи!D8 | E34: =IFERROR(D34/C34,"") | G34: =IFERROR(C34/4,"") | I34: =IFERROR(H34/G34,"") | K34: =IFERROR(C34/4,"") | M34: =IFERROR(L34/K34,"") | O34: =IFERROR(C34/4,"") | Q34: =IFERROR(P34/O34,"") | S34: =IFERROR(C34/4,"") | U34: =IFERROR(T34/S34,"")
B35: Проведено встреч (шт.) | D35: =Продажи!D9 | E35: =IFERROR(D35/C35,"") | G35: =IFERROR(C35/4,"") | I35: =IFERROR(H35/G35,"") | K35: =IFERROR(C35/4,"") | M35: =IFERROR(L35/K35,"") | O35: =IFERROR(C35/4,"") | Q35: =IFERROR(P35/O35,"") | S35: =IFERROR(C35/4,"") | U35: =IFERROR(T35/S35,"")
B36: Количество продаж (шт.) | D36: =Продажи!D10 | E36: =IFERROR(D36/C36,"") | G36: =IFERROR(C36/4,"") | I36: =IFERROR(H36/G36,"") | K36: =IFERROR(C36/4,"") | M36: =IFERROR(L36/K36,"") | O36: =IFERROR(C36/4,"") | Q36: =IFERROR(P36/O36,"") | S36: =IFERROR(C36/4,"") | U36: =IFERROR(T36/S36,"")
B37: Сумма продаж (₽) | D37: =Продажи!D11 | E37: =IFERROR(D37/C37,"") | G37: =IFERROR(C37/4,"") | I37: =IFERROR(H37/G37,"") | K37: =IFERROR(C37/4,"") | M37: =IFERROR(L37/K37,"") | O37: =IFERROR(C37/4,"") | Q37: =IFERROR(P37/O37,"") | S37: =IFERROR(C37/4,"") | U37: =IFERROR(T37/S37,"")
B38: Средний чек (₽) | D38: =Продажи!D12 | E38: =IFERROR(D38/C38,"") | G38: =IFERROR(C38/4,"") | I38: =IFERROR(H38/G38,"") | K38: =IFERROR(C38/4,"") | M38: =IFERROR(L38/K38,"") | O38: =IFERROR(C38/4,"") | Q38: =IFERROR(P38/O38,"") | S38: =IFERROR(C38/4,"") | U38: =IFERROR(T38/S38,"")
B40: КОНВЕРСИИ ВОРОНКИ (авто-расчёт)
B41: CV лид → КП (%) | C41: =IFERROR(C33/C32,"") | D41: =IFERROR(D33/D32,"") | E41: =IFERROR(D41/C41,"") | G41: =IFERROR(G33/G32,"") | H41: =IFERROR(H33/H32,"") | I41: =IFERROR(H41/G41,"") | K41: =IFERROR(K33/K32,"") | L41: =IFERROR(L33/L32,"") | M41: =IFERROR(L41/K41,"") | O41: =IFERROR(O33/O32,"") | P41: =IFERROR(P33/P32,"") | Q41: =IFERROR(P41/O41,"") | S41: =IFERROR(S33/S32,"") | T41: =IFERROR(T33/T32,"") | U41: =IFERROR(T41/S41,"")
B42: CV КП → встреча (%) | C42: =IFERROR(C35/C33,"") | D42: =IFERROR(D35/D33,"") | E42: =IFERROR(D42/C42,"") | G42: =IFERROR(G35/G33,"") | H42: =IFERROR(H35/H33,"") | I42: =IFERROR(H42/G42,"") | K42: =IFERROR(K35/K33,"") | L42: =IFERROR(L35/L33,"") | M42: =IFERROR(L42/K42,"") | O42: =IFERROR(O35/O33,"") | P42: =IFERROR(P35/P33,"") | Q42: =IFERROR(P42/O42,"") | S42: =IFERROR(S35/S33,"") | T42: =IFERROR(T35/T33,"") | U42: =IFERROR(T42/S42,"")
B43: CV встреча → продажа (%) | C43: =IFERROR(C36/C35,"") | D43: =IFERROR(D36/D35,"") | E43: =IFERROR(D43/C43,"") | G43: =IFERROR(G36/G35,"") | H43: =IFERROR(H36/H35,"") | I43: =IFERROR(H43/G43,"") | K43: =IFERROR(K36/K35,"") | L43: =IFERROR(L36/L35,"") | M43: =IFERROR(L43/K43,"") | O43: =IFERROR(O36/O35,"") | P43: =IFERROR(P36/P35,"") | Q43: =IFERROR(P43/O43,"") | S43: =IFERROR(S36/S35,"") | T43: =IFERROR(T36/T35,"") | U43: =IFERROR(T43/S43,"")
B44: CV лид → продажа (%) | C44: =IFERROR(C36/C32,"") | D44: =IFERROR(D36/D32,"") | E44: =IFERROR(D44/C44,"") | G44: =IFERROR(G36/G32,"") | H44: =IFERROR(H36/H32,"") | I44: =IFERROR(H44/G44,"") | K44: =IFERROR(K36/K32,"") | L44: =IFERROR(L36/L32,"") | M44: =IFERROR(L44/K44,"") | O44: =IFERROR(O36/O32,"") | P44: =IFERROR(P36/P32,"") | Q44: =IFERROR(P44/O44,"") | S44: =IFERROR(S36/S32,"") | T44: =IFERROR(T36/T32,"") | U44: =IFERROR(T44/S44,"")
B46: ЗАДАЧИ НЕДЕЛИ — трекинг исполнения
...

Sheet Маркетинг
B2: Маркетинг — детализация по каналам и дням | I2: Nexops · opdir.nexops.ru
B3: Месяц: | D3: Дней в месяце: | F3: =DAY(EOMONTH(TODAY(),0))
B5: Метрика | C5: ПЛАН МЕС | D5: ФАКТ МЕС | E5: % | F5: ПРОГНОЗ | G5: %прог | J5: Неделя 1 | R5: Неделя 2 | Z5: Неделя 3 | AH5: Неделя 4 | AP5: Неделя 5 | AX5: Неделя 6
C6: ПЛАН | D6: ФАКТ | E6: % | F6: ПРГ | G6: % | J6: ПН | K6: ВТ | L6: СР | M6: ЧТ | N6: ПТ | O6: СБ | P6: ВС | R6: ПН | S6: ВТ | T6: СР | U6: ЧТ | V6: ПТ | W6: СБ | X6: ВС | Z6: ПН | AA6: ВТ | AB6: СР | AC6: ЧТ | AD6: ПТ | AE6: СБ | AF6: ВС | AH6: ПН | AI6: ВТ | AJ6: СР | AK6: ЧТ | AL6: ПТ | AM6: СБ | AN6: ВС | AP6: ПН | AQ6: ВТ | AR6: СР | AS6: ЧТ | AT6: ПТ | AU6: СБ | AV6: ВС | AX6: ПН | AY6: ВТ | AZ6: СР | BA6: ЧТ | BB6: ПТ | BC6: СБ | BD6: ВС
B7: МАРКЕТИНГ — ОБЩИЙ
B8: Суммарный бюджет (₽) | D8: =SUM(SUM(J8:P8)+SUM(R8:X8)+SUM(Z8:AF8)+SUM(AH8:AN8)+SUM(AP8:AV8)+SUM(AX8:BD8)) | E8: =IFERROR(D8/C8,"") | F8: =IFERROR(D8/IF(DAY(TODAY())=0,1,DAY(TODAY()))*G3,"") | G8: =IFERROR(F8/C8,"")
B9: Стоимость лида (₽) | D9: =SUM(SUM(J9:P9)+SUM(R9:X9)+SUM(Z9:AF9)+SUM(AH9:AN9)+SUM(AP9:AV9)+SUM(AX9:BD9)) | E9: =IFERROR(D9/C9,"") | F9: =IFERROR(D9/IF(DAY(TODAY())=0,1,DAY(TODAY()))*G3,"") | G9: =IFERROR(F9/C9,"")
B10: Стоимость клиента (₽) | D10: =SUM(SUM(J10:P10)+SUM(R10:X10)+SUM(Z10:AF10)+SUM(AH10:AN10)+SUM(AP10:AV10)+SUM(AX10:BD10)) | E10: =IFERROR(D10/C10,"") | F10: =IFERROR(D10/IF(DAY(TODAY())=0,1,DAY(TODAY()))*G3,"") | G10: =IFERROR(F10/C10,"")
B11: Кол-во лидов (шт.) | D11: =SUM(SUM(J11:P11)+SUM(R11:X11)+SUM(Z11:AF11)+SUM(AH11:AN11)+SUM(AP11:AV11)+SUM(AX11:BD11)) | E11: =IFERROR(D11/C11,"") | F11: =IFERROR(D11/IF(DAY(TODAY())=0,1,DAY(TODAY()))*G3,"") | G11: =IFERROR(F11/C11,"")
B13: TG-КАНАЛ
B14: Бюджет Telegram (₽) | D14: =SUM(SUM(J14:P14)+SUM(R14:X14)+SUM(Z14:AF14)+SUM(AH14:AN14)+SUM(AP14:AV14)+SUM(AX14:BD14)) | E14: =IFERROR(D14/C14,"") | F14: =IFERROR(D14/IF(DAY(TODAY())=0,1,DAY(TODAY()))*G3,"") | G14: =IFERROR(F14/C14,"")
B15: Подписчики (накоп.) | D15: =SUM(SUM(J15:P15)+SUM(R15:X15)+SUM(Z15:AF15)+SUM(AH15:AN15)+SUM(AP15:AV15)+SUM(AX15:BD15)) | E15: =IFERROR(D15/C15,"") | F15: =IFERROR(D15/IF(DAY(TODAY())=0,1,DAY(TODAY()))*G3,"") | G15: =IFERROR(F15/C15,"")
B16: Прирост за период | D16: =SUM(SUM(J16:P16)+SUM(R16:X16)+SUM(Z16:AF16)+SUM(AH16:AN16)+SUM(AP16:AV16)+SUM(AX16:BD16)) | E16: =IFERROR(D16/C16,"") | F16: =IFERROR(D16/IF(DAY(TODAY())=0,1,DAY(TODAY()))*G3,"") | G16: =IFERROR(F16/C16,"")
B17: Контентных единиц | D17: =SUM(SUM(J17:P17)+SUM(R17:X17)+SUM(Z17:AF17)+SUM(AH17:AN17)+SUM(AP17:AV17)+SUM(AX17:BD17)) | E17: =IFERROR(D17/C17,"") | F17: =IFERROR(D17/IF(DAY(TODAY())=0,1,DAY(TODAY()))*G3,"") | G17: =IFERROR(F17/C17,"")
B18: Лиды из Telegram | D18: =SUM(SUM(J18:P18)+SUM(R18:X18)+SUM(Z18:AF18)+SUM(AH18:AN18)+SUM(AP18:AV18)+SUM(AX18:BD18)) | E18: =IFERROR(D18/C18,"") | F18: =IFERROR(D18/IF(DAY(TODAY())=0,1,DAY(TODAY()))*G3,"") | G18: =IFERROR(F18/C18,"")
B19: Стоимость лида TG (₽) | D19: =SUM(SUM(J19:P19)+SUM(R19:X19)+SUM(Z19:AF19)+SUM(AH19:AN19)+SUM(AP19:AV19)+SUM(AX19:BD19)) | E19: =IFERROR(D19/C19,"") | F19: =IFERROR(D19/IF(DAY(TODAY())=0,1,DAY(TODAY()))*G3,"") | G19: =IFERROR(F19/C19,"")
B21: ПОСЕВЫ / INSTAGRAM
B22: Бюджет (₽) | D22: =SUM(SUM(J22:P22)+SUM(R22:X22)+SUM(Z22:AF22)+SUM(AH22:AN22)+SUM(AP22:AV22)+SUM(AX22:BD22)) | E22: =IFERROR(D22/C22,"") | F22: =IFERROR(D22/IF(DAY(TODAY())=0,1,DAY(TODAY()))*G3,"") | G22: =IFERROR(F22/C22,"")
B23: Кол-во размещений | D23: =SUM(SUM(J23:P23)+SUM(R23:X23)+SUM(Z23:AF23)+SUM(AH23:AN23)+SUM(AP23:AV23)+SUM(AX23:BD23)) | E23: =IFERROR(D23/C23,"") | F23: =IFERROR(D23/IF(DAY(TODAY())=0,1,DAY(TODAY()))*G3,"") | G23: =IFERROR(F23/C23,"")
B24: Просмотры постов | D24: =SUM(SUM(J24:P24)+SUM(R24:X24)+SUM(Z24:AF24)+SUM(AH24:AN24)+SUM(AP24:AV24)+SUM(AX24:BD24)) | E24: =IFERROR(D24/C24,"") | F24: =IFERROR(D24/IF(DAY(TODAY())=0,1,DAY(TODAY()))*G3,"") | G24: =IFERROR(F24/C24,"")
B25: Переходы | D25: =SUM(SUM(J25:P25)+SUM(R25:X25)+SUM(Z25:AF25)+SUM(AH25:AN25)+SUM(AP25:AV25)+SUM(AX25:BD25)) | E25: =IFERROR(D25/C25,"") | F25: =IFERROR(D25/IF(DAY(TODAY())=0,1,DAY(TODAY()))*G3,"") | G25: =IFERROR(F25/C25,"")
B26: Лиды из посевов | D26: =SUM(SUM(J26:P26)+SUM(R26:X26)+SUM(Z26:AF26)+SUM(AH26:AN26)+SUM(AP26:AV26)+SUM(AX26:BD26)) | E26: =IFERROR(D26/C26,"") | F26: =IFERROR(D26/IF(DAY(TODAY())=0,1,DAY(TODAY()))*G3,"") | G26: =IFERROR(F26/C26,"")
B27: Стоимость лида (₽) | D27: =SUM(SUM(J27:P27)+SUM(R27:X27)+SUM(Z27:AF27)+SUM(AH27:AN27)+SUM(AP27:AV27)+SUM(AX27:BD27)) | E27: =IFERROR(D27/C27,"") | F27: =IFERROR(D27/IF(DAY(TODAY())=0,1,DAY(TODAY()))*G3,"") | G27: =IFERROR(F27/C27,"")
B29: YOUTUBE
B30: Бюджет YouTube (₽) | D30: =SUM(SUM(J30:P30)+SUM(R30:X30)+SUM(Z30:AF30)+SUM(AH30:AN30)+SUM(AP30:AV30)+SUM(AX30:BD30)) | E30: =IFERROR(D30/C30,"") | F30: =IFERROR(D30/IF(DAY(TODAY())=0,1,DAY(TODAY()))*G3,"") | G30: =IFERROR(F30/C30,"")
B31: Подписчики (накоп.) | D31: =SUM(SUM(J31:P31)+SUM(R31:X31)+SUM(Z31:AF31)+SUM(AH31:AN31)+SUM(AP31:AV31)+SUM(AX31:BD31)) | E31: =IFERROR(D31/C31,"") | F31: =IFERROR(D31/IF(DAY(TODAY())=0,1,DAY(TODAY()))*G3,"") | G31: =IFERROR(F31/C31,"")
B32: Контентных единиц | D32: =SUM(SUM(J32:P32)+SUM(R32:X32)+SUM(Z32:AF32)+SUM(AH32:AN32)+SUM(AP32:AV32)+SUM(AX32:BD32)) | E32: =IFERROR(D32/C32,"") | F32: =IFERROR(D32/IF(DAY(TODAY())=0,1,DAY(TODAY()))*G3,"") | G32: =IFERROR(F32/C32,"")
B33: Просмотры | D33: =SUM(SUM(J33:P33)+SUM(R33:X33)+SUM(Z33:AF33)+SUM(AH33:AN33)+SUM(AP33:AV33)+SUM(AX33:BD33)) | E33: =IFERROR(D33/C33,"") | F33: =IFERROR(D33/IF(DAY(TODAY())=0,1,DAY(TODAY()))*G3,"") | G33: =IFERROR(F33/C33,"")
B34: Лиды из YouTube | D34: =SUM(SUM(J34:P34)+SUM(R34:X34)+SUM(Z34:AF34)+SUM(AH34:AN34)+SUM(AP34:AV34)+SUM(AX34:BD34)) | E34: =IFERROR(D34/C34,"") | F34: =IFERROR(D34/IF(DAY(TODAY())=0,1,DAY(TODAY()))*G3,"") | G34: =IFERROR(F34/C34,"")
B35: Стоимость лида YT (₽) | D35: =SUM(SUM(J35:P35)+SUM(R35:X35)+SUM(Z35:AF35)+SUM(AH35:AN35)+SUM(AP35:AV35)+SUM(AX35:BD35)) | E35: =IFERROR(D35/C35,"") | F35: =IFERROR(D35/IF(DAY(TODAY())=0,1,DAY(TODAY()))*G3,"") | G35: =IFERROR(F35/C35,"")
B37: АВИТО / ДРУГИЕ КАНАЛЫ
B38: Бюджет Авито (₽) | D38: =SUM(SUM(J38:P38)+SUM(R38:X38)+SUM(Z38:AF38)+SUM(AH38:AN38)+SUM(AP38:AV38)+SUM(AX38:BD38)) | E38: =IFERROR(D38/C38,"") | F38: =IFERROR(D38/IF(DAY(TODAY())=0,1,DAY(TODAY()))*G3,"") | G38: =IFERROR(F38/C38,"")
B39: Активных объявлений | D39: =SUM(SUM(J39:P39)+SUM(R39:X39)+SUM(Z39:AF39)+SUM(AH39:AN39)+SUM(AP39:AV39)+SUM(AX39:BD39)) | E39: =IFERROR(D39/C39,"") | F39: =IFERROR(D39/IF(DAY(TODAY())=0,1,DAY(TODAY()))*G3,"") | G39: =IFERROR(F39/C39,"")
B40: Лиды из Авито | D40: =SUM(SUM(J40:P40)+SUM(R40:X40)+SUM(Z40:AF40)+SUM(AH40:AN40)+SUM(AP40:AV40)+SUM(AX40:BD40)) | E40: =IFERROR(D40/C40,"") | F40: =IFERROR(D40/IF(DAY(TODAY())=0,1,DAY(TODAY()))*G3,"") | G40: =IFERROR(F40/C40,"")
B41: Лиды по рекомендации | D41: =SUM(SUM(J41:P41)+SUM(R41:X41)+SUM(Z41:AF41)+SUM(AH41:AN41)+SUM(AP41:AV41)+SUM(AX41:BD41)) | E41: =IFERROR(D41/C41,"") | F41: =IFERROR(D41/IF(DAY(TODAY())=0,1,DAY(TODAY()))*G3,"") | G41: =IFERROR(F41/C41,"")
B42: Лиды — другой канал | D42: =SUM(SUM(J42:P42)+SUM(R42:X42)+SUM(Z42:AF42)+SUM(AH42:AN42)+SUM(AP42:AV42)+SUM(AX42:BD42)) | E42: =IFERROR(D42/C42,"") | F42: =IFERROR(D42/IF(DAY(TODAY())=0,1,DAY(TODAY()))*G3,"") | G42: =IFERROR(F42/C42,"")

Sheet Продажи
B2: Продажи — детализация по менеджерам и дням
C3: МЕС ПЛАН | D3: МЕС ФАКТ | E3: % | F3: ПРОГНОЗ | G3: %прог | J3: Неделя 1 | R3: Неделя 2 | Z3: Неделя 3 | AH3: Неделя 4 | AP3: Неделя 5 | AX3: Неделя 6
B4: Метрика | C4: ПЛАН | D4: ФАКТ | E4: % | F4: ПРОГН | G4: %пр | J4: ПН | K4: ВТ | L4: СР | M4: ЧТ | N4: ПТ | O4: СБ | P4: ВС | R4: ПН | S4: ВТ | T4: СР | U4: ЧТ | V4: ПТ | W4: СБ | X4: ВС | Z4: ПН | AA4: ВТ | AB4: СР | AC4: ЧТ | AD4: ПТ | AE4: СБ | AF4: ВС | AH4: ПН | AI4: ВТ | AJ4: СР | AK4: ЧТ | AL4: ПТ | AM4: СБ | AN4: ВС | AP4: ПН | AQ4: ВТ | AR4: СР | AS4: ЧТ | AT4: ПТ | AU4: СБ | AV4: ВС | AX4: ПН | AY4: ВТ | AZ4: СР | BA4: ЧТ | BB4: ПТ | BC4: СБ | BD4: ВС
B5: ИТОГО — ВСЕ МЕНЕДЖЕРЫ
B6: Новых лидов (шт.) | C6: =C16+C26+C36 | D6: =D16+D26+D36 | E6: =IFERROR(D6/C6,"") | F6: =IFERROR(D6/IF(DAY(TODAY())=0,1,DAY(TODAY()))*G3,"") | G6: =IFERROR(F6/C6,"")
B7: КП отправлено (шт.) | C7: =C17+C27+C37 | D7: =D17+D27+D37 | E7: =IFERROR(D7/C7,"") | F7: =IFERROR(D7/IF(DAY(TODAY())=0,1,DAY(TODAY()))*G3,"") | G7: =IFERROR(F7/C7,"")
B8: Назначено встреч (шт.) | C8: =C18+C28+C38 | D8: =D18+D28+D38 | E8: =IFERROR(D8/C8,"") | F8: =IFERROR(D8/IF(DAY(TODAY())=0,1,DAY(TODAY()))*G3,"") | G8: =IFERROR(F8/C8,"")
B9: Проведено встреч (шт.) | C9: =C19+C29+C39 | D9: =D19+D29+D39 | E9: =IFERROR(D9/C9,"") | F9: =IFERROR(D9/IF(DAY(TODAY())=0,1,DAY(TODAY()))*G3,"") | G9: =IFERROR(F9/C9,"")
B10: Кол-во продаж (шт.) | C10: =C20+C30+C40 | D10: =D20+D30+D40 | E10: =IFERROR(D10/C10,"") | F10: =IFERROR(D10/IF(DAY(TODAY())=0,1,DAY(TODAY()))*G3,"") | G10: =IFERROR(F10/C10,"")
B11: Сумма продаж (₽) | C11: =C21+C31+C41 | D11: =D21+D31+D41 | E11: =IFERROR(D11/C11,"") | F11: =IFERROR(D11/IF(DAY(TODAY())=0,1,DAY(TODAY()))*G3,"") | G11: =IFERROR(F11/C11,"")
B12: Средний чек (₽) | D12: =IFERROR((D21+D31+D41)/(D20+D30+D40),"") | E12: =IFERROR(D12/C12,"") | F12: =IFERROR(D12/IF(DAY(TODAY())=0,1,DAY(TODAY()))*G3,"") | G12: =IFERROR(F12/C12,"")
B13: CV лид→продажа (%) | C13: =IFERROR((C20+C30+C40)/(C16+C26+C36),"") | D13: =IFERROR((D20+D30+D40)/(D16+D26+D36),"") | E13: =IFERROR(D13/C13,"") | F13: =IFERROR(D13/IF(DAY(TODAY())=0,1,DAY(TODAY()))*G3,"") | G13: =IFERROR(F13/C13,"")
B15: МЕНЕДЖЕР 1
B16: Новых лидов (шт.) | D16: =SUM(J16:P16)+SUM(R16:X16)+SUM(Z16:AF16)+SUM(AH16:AN16)+SUM(AP16:AV16)+SUM(AX16:BD16) | E16: =IFERROR(D16/C16,"") | F16: =IFERROR(D16/IF(DAY(TODAY())=0,1,DAY(TODAY()))*G3,"") | G16: =IFERROR(F16/C16,"")
B17: КП отправлено (шт.) | D17: =SUM(J17:P17)+SUM(R17:X17)+SUM(Z17:AF17)+SUM(AH17:AN17)+SUM(AP17:AV17)+SUM(AX17:BD17) | E17: =IFERROR(D17/C17,"") | F17: =IFERROR(D17/IF(DAY(TODAY())=0,1,DAY(TODAY()))*G3,"") | G17: =IFERROR(F17/C17,"")
B18: Назначено встреч (шт.) | D18: =SUM(J18:P18)+SUM(R18:X18)+SUM(Z18:AF18)+SUM(AH18:AN18)+SUM(AP18:AV18)+SUM(AX18:BD18) | E18: =IFERROR(D18/C18,"") | F18: =IFERROR(D18/IF(DAY(TODAY())=0,1,DAY(TODAY()))*G3,"") | G18: =IFERROR(F18/C18,"")
B19: Проведено встреч (шт.) | D19: =SUM(J19:P19)+SUM(R19:X19)+SUM(Z19:AF19)+SUM(AH19:AN19)+SUM(AP19:AV19)+SUM(AX19:BD19) | E19: =IFERROR(D19/C19,"") | F19: =IFERROR(D19/IF(DAY(TODAY())=0,1,DAY(TODAY()))*G3,"") | G19: =IFERROR(F19/C19,"")
B20: Кол-во продаж (шт.) | D20: =SUM(J20:P20)+SUM(R20:X20)+SUM(Z20:AF20)+SUM(AH20:AN20)+SUM(AP20:AV20)+SUM(AX20:BD20) | E20: =IFERROR(D20/C20,"") | F20: =IFERROR(D20/IF(DAY(TODAY())=0,1,DAY(TODAY()))*G3,"") | G20: =IFERROR(F20/C20,"")
B21: Сумма продаж (₽) | D21: =SUM(J21:P21)+SUM(R21:X21)+SUM(Z21:AF21)+SUM(AH21:AN21)+SUM(AP21:AV21)+SUM(AX21:BD21) | E21: =IFERROR(D21/C21,"") | F21: =IFERROR(D21/IF(DAY(TODAY())=0,1,DAY(TODAY()))*G3,"") | G21: =IFERROR(F21/C21,"")
B22: Средний чек (₽) | C22: =IFERROR(C21/C20,"") | D22: =IFERROR(D21/D20,"") | E22: =IFERROR(D22/C22,"") | F22: =IFERROR(D22/IF(DAY(TODAY())=0,1,DAY(TODAY()))*G3,"") | G22: =IFERROR(F22/C22,"")
B23: CV лид→продажа (%) | C23: =IFERROR(C20/C16,"") | D23: =IFERROR(D20/D16,"") | E23: =IFERROR(D23/C23,"")
B25: МЕНЕДЖЕР 2
B26: Новых лидов (шт.) | D26: =SUM(J26:P26)+SUM(R26:X26)+SUM(Z26:AF26)+SUM(AH26:AN26)+SUM(AP26:AV26)+SUM(AX26:BD26) | E26: =IFERROR(D26/C26,"") | F26: =IFERROR(D26/IF(DAY(TODAY())=0,1,DAY(TODAY()))*G3,"") | G26: =IFERROR(F26/C26,"")
B27: КП отправлено (шт.) | D27: =SUM(J27:P27)+SUM(R27:X27)+SUM(Z27:AF27)+SUM(AH27:AN27)+SUM(AP27:AV27)+SUM(AX27:BD27) | E27: =IFERROR(D27/C27,"") | F27: =IFERROR(D27/IF(DAY(TODAY())=0,1,DAY(TODAY()))*G3,"") | G27: =IFERROR(F27/C27,"")
B28: Назначено встреч (шт.) | D28: =SUM(J28:P28)+SUM(R28:X28)+SUM(Z28:AF28)+SUM(AH28:AN28)+SUM(AP28:AV28)+SUM(AX28:BD28) | E28: =IFERROR(D28/C28,"") | F28: =IFERROR(D28/IF(DAY(TODAY())=0,1,DAY(TODAY()))*G3,"") | G28: =IFERROR(F28/C28,"")
B29: Проведено встреч (шт.) | D29: =SUM(J29:P29)+SUM(R29:X29)+SUM(Z29:AF29)+SUM(AH29:AN29)+SUM(AP29:AV29)+SUM(AX29:BD29) | E29: =IFERROR(D29/C29,"") | F29: =IFERROR(D29/IF(DAY(TODAY())=0,1,DAY(TODAY()))*G3,"") | G29: =IFERROR(F29/C29,"")
B30: Кол-во продаж (шт.) | D30: =SUM(J30:P30)+SUM(R30:X30)+SUM(Z30:AF30)+SUM(AH30:AN30)+SUM(AP30:AV30)+SUM(AX30:BD30) | E30: =IFERROR(D30/C30,"") | F30: =IFERROR(D30/IF(DAY(TODAY())=0,1,DAY(TODAY()))*G3,"") | G30: =IFERROR(F30/C30,"")
B31: Сумма продаж (₽) | D31: =SUM(J31:P31)+SUM(R31:X31)+SUM(Z31:AF31)+SUM(AH31:AN31)+SUM(AP31:AV31)+SUM(AX31:BD31) | E31: =IFERROR(D31/C31,"") | F31: =IFERROR(D31/IF(DAY(TODAY())=0,1,DAY(TODAY()))*G3,"") | G31: =IFERROR(F31/C31,"")
B32: Средний чек (₽) | C32: =IFERROR(C31/C30,"") | D32: =IFERROR(D31/D30,"") | E32: =IFERROR(D32/C32,"") | F32: =IFERROR(D32/IF(DAY(TODAY())=0,1,DAY(TODAY()))*G3,"") | G32: =IFERROR(F32/C32,"")
B33: CV лид→продажа (%) | C33: =IFERROR(C30/C26,"") | D33: =IFERROR(D30/D26,"") | E33: =IFERROR(D33/C33,"")
B35: МЕНЕДЖЕР 3
B36: Новых лидов (шт.) | D36: =SUM(J36:P36)+SUM(R36:X36)+SUM(Z36:AF36)+SUM(AH36:AN36)+SUM(AP36:AV36)+SUM(AX36:BD36) | E36: =IFERROR(D36/C36,"") | F36: =IFERROR(D36/IF(DAY(TODAY())=0,1,DAY(TODAY()))*G3,"") | G36: =IFERROR(F36/C36,"")
B37: КП отправлено (шт.) | D37: =SUM(J37:P37)+SUM(R37:X37)+SUM(Z37:AF37)+SUM(AH37:AN37)+SUM(AP37:AV37)+SUM(AX37:BD37) | E37: =IFERROR(D37/C37,"") | F37: =IFERROR(D37/IF(DAY(TODAY())=0,1,DAY(TODAY()))*G3,"") | G37: =IFERROR(F37/C37,"")
B38: Назначено встреч (шт.) | D38: =SUM(J38:P38)+SUM(R38:X38)+SUM(Z38:AF38)+SUM(AH38:AN38)+SUM(AP38:AV38)+SUM(AX38:BD38) | E38: =IFERROR(D38/C38,"") | F38: =IFERROR(D38/IF(DAY(TODAY())=0,1,DAY(TODAY()))*G3,"") | G38: =IFERROR(F38/C38,"")
B39: Проведено встреч (шт.) | D39: =SUM(J39:P39)+SUM(R39:X39)+SUM(Z39:AF39)+SUM(AH39:AN39)+SUM(AP39:AV39)+SUM(AX39:BD39) | E39: =IFERROR(D39/C39,"") | F39: =IFERROR(D39/IF(DAY(TODAY())=0,1,DAY(TODAY()))*G3,"") | G39: =IFERROR(F39/C39,"")
B40: Кол-во продаж (шт.) | D40: =SUM(J40:P40)+SUM(R40:X40)+SUM(Z40:AF40)+SUM(AH40:AN40)+SUM(AP40:AV40)+SUM(AX40:BD40) | E40: =IFERROR(D40/C40,"") | F40: =IFERROR(D40/IF(DAY(TODAY())=0,1,DAY(TODAY()))*G3,"") | G40: =IFERROR(F40/C40,"")
B41: Сумма продаж (₽) | D41: =SUM(J41:P41)+SUM(R41:X41)+SUM(Z41:AF41)+SUM(AH41:AN41)+SUM(AP41:AV41)+SUM(AX41:BD41) | E41: =IFERROR(D41/C41,"") | F41: =IFERROR(D41/IF(DAY(TODAY())=0,1,DAY(TODAY()))*G3,"") | G41: =IFERROR(F41/C41,"")
B42: Средний чек (₽) | C42: =IFERROR(C41/C40,"") | D42: =IFERROR(D41/D40,"") | E42: =IFERROR(D42/C42,"") | F42: =IFERROR(D42/IF(DAY(TODAY())=0,1,DAY(TODAY()))*G3,"") | G42: =IFERROR(F42/C42,"")
B43: CV лид→продажа (%) | C43: =IFERROR(C40/C36,"") | D43: =IFERROR(D40/D36,"") | E43: =IFERROR(D43/C43,"")
